Watching for file changes with StatReloader
Watching for file changes with StatReloader
Internal Server Error: /vw/generate/
Traceback (most recent call last):
  File "/home/ubuntu/.local/lib/python3.5/site-packages/django/core/handlers/exception.py", line 34, in inner
    response = get_response(request)
  File "/home/ubuntu/.local/lib/python3.5/site-packages/django/core/handlers/base.py", line 115, in _get_response
    response = self.process_exception_by_middleware(e, request)
  File "/home/ubuntu/.local/lib/python3.5/site-packages/django/core/handlers/base.py", line 113, in _get_response
    response = wrapped_callback(request, *callback_args, **callback_kwargs)
  File "/data/django/mysite_git/VisualWallet-backend/mysite/qr/views.py", line 28, in genSplit
    res, carrier, length, width, c1, c2, c3 = api1(sk, k, n, "", "")
  File "/data/django/mysite_git/VisualWallet-backend/mysite/qr/kn/shadow_gen_kn.py", line 299, in api1
    data_matrix, carrier_matrix, length, width, c1, c2, c3 = apiFirst(msg, k, n, cmsg, BTCLOGO, ES, "BTC", 1)
  File "/data/django/mysite_git/VisualWallet-backend/mysite/qr/kn/shadow_gen_kn.py", line 257, in apiFirst
    img.save(CARRIERPATH+str(i)+".png")
  File "/home/ubuntu/.local/lib/python3.5/site-packages/qrcode/image/pil.py", line 50, in save
    self._img.save(stream, format=format, **kwargs)
  File "/home/ubuntu/.local/lib/python3.5/site-packages/PIL/Image.py", line 2155, in save
    fp = builtins.open(filename, "w+b")
FileNotFoundError: [Errno 2] No such file or directory: 'qr/kn/imgs/carrier0.png'
[29/Apr/2021 23:41:26] "POST /vw/generate/ HTTP/1.1" 500 88053
Internal Server Error: /vw/generate/
Traceback (most recent call last):
  File "/home/ubuntu/.local/lib/python3.5/site-packages/django/core/handlers/exception.py", line 34, in inner
    response = get_response(request)
  File "/home/ubuntu/.local/lib/python3.5/site-packages/django/core/handlers/base.py", line 115, in _get_response
    response = self.process_exception_by_middleware(e, request)
  File "/home/ubuntu/.local/lib/python3.5/site-packages/django/core/handlers/base.py", line 113, in _get_response
    response = wrapped_callback(request, *callback_args, **callback_kwargs)
  File "/data/django/mysite_git/VisualWallet-backend/mysite/qr/views.py", line 28, in genSplit
    res, carrier, length, width, c1, c2, c3 = api1(sk, k, n, "", "")
  File "/data/django/mysite_git/VisualWallet-backend/mysite/qr/kn/shadow_gen_kn.py", line 299, in api1
    data_matrix, carrier_matrix, length, width, c1, c2, c3 = apiFirst(msg, k, n, cmsg, BTCLOGO, ES, "BTC", 1)
  File "/data/django/mysite_git/VisualWallet-backend/mysite/qr/kn/shadow_gen_kn.py", line 257, in apiFirst
    img.save(CARRIERPATH+str(i)+".png")
  File "/home/ubuntu/.local/lib/python3.5/site-packages/qrcode/image/pil.py", line 50, in save
    self._img.save(stream, format=format, **kwargs)
  File "/home/ubuntu/.local/lib/python3.5/site-packages/PIL/Image.py", line 2155, in save
    fp = builtins.open(filename, "w+b")
FileNotFoundError: [Errno 2] No such file or directory: 'qr/kn/imgs/carrier0.png'
[29/Apr/2021 23:47:40] "POST /vw/generate/ HTTP/1.1" 500 88053
/data/django/mysite_git/VisualWallet-backend/mysite/qr/kn/global_var.py changed, reloading.
Performing system checks...

System check identified no issues (0 silenced).
April 29, 2021 - 23:41:18
Django version 2.2.20, using settings 'mysite.settings'
Starting development server at http://0.0.0.0:8000/
Quit the server with CONTROL-C.
Watching for file changes with StatReloader
